{
 "cells": [
  {
   "cell_type": "code",
   "execution_count": 3,
   "id": "c18a5fd3-2605-489a-830c-270bb5dfc357",
   "metadata": {},
   "outputs": [
    {
     "ename": "ModuleNotFoundError",
     "evalue": "No module named 'pandas'",
     "output_type": "error",
     "traceback": [
      "\u001b[0;31m---------------------------------------------------------------------------\u001b[0m",
      "\u001b[0;31mModuleNotFoundError\u001b[0m                       Traceback (most recent call last)",
      "Cell \u001b[0;32mIn[3], line 2\u001b[0m\n\u001b[1;32m      1\u001b[0m \u001b[38;5;28;01mimport\u001b[39;00m \u001b[38;5;21;01mnumpy\u001b[39;00m \u001b[38;5;28;01mas\u001b[39;00m \u001b[38;5;21;01mnp\u001b[39;00m\n\u001b[0;32m----> 2\u001b[0m \u001b[38;5;28;01mimport\u001b[39;00m \u001b[38;5;21;01mpandas\u001b[39;00m \u001b[38;5;28;01mas\u001b[39;00m \u001b[38;5;21;01mpd\u001b[39;00m\n\u001b[1;32m      3\u001b[0m arr\u001b[38;5;241m=\u001b[39mnp\u001b[38;5;241m.\u001b[39marray([[\u001b[38;5;241m1\u001b[39m,\u001b[38;5;241m2\u001b[39m,\u001b[38;5;241m3\u001b[39m],[\u001b[38;5;241m4\u001b[39m,\u001b[38;5;241m5\u001b[39m,\u001b[38;5;241m6\u001b[39m]])\n\u001b[1;32m      4\u001b[0m df\u001b[38;5;241m=\u001b[39mpd\u001b[38;5;241m.\u001b[39mDataFrame(arr)\n",
      "\u001b[0;31mModuleNotFoundError\u001b[0m: No module named 'pandas'"
     ]
    }
   ],
   "source": [
    "import numpy as np\n",
    "import pandas as pd\n",
    "arr=np.array([[1,2,3],[4,5,6]])\n",
    "df=pd.DataFrame(arr)\n",
    "df"
   ]
  },
  {
   "cell_type": "code",
   "execution_count": 4,
   "id": "d010a474-124d-4784-bacb-19ec919d33a5",
   "metadata": {},
   "outputs": [
    {
     "name": "stdout",
     "output_type": "stream",
     "text": [
      "Defaulting to user installation because normal site-packages is not writeable\n",
      "Collecting numpy\n",
      "  Using cached numpy-1.24.4-cp38-cp38-manylinux_2_17_x86_64.manylinux2014_x86_64.whl.metadata (5.6 kB)\n",
      "Using cached numpy-1.24.4-cp38-cp38-manylinux_2_17_x86_64.manylinux2014_x86_64.whl (17.3 MB)\n",
      "Installing collected packages: numpy\n",
      "Successfully installed numpy-1.24.4\n",
      "Note: you may need to restart the kernel to use updated packages.\n"
     ]
    }
   ],
   "source": [
    "pip install numpy"
   ]
  },
  {
   "cell_type": "code",
   "execution_count": 2,
   "id": "aaaf2d36-b769-44b2-ab89-e0a5cb15f768",
   "metadata": {},
   "outputs": [
    {
     "name": "stdout",
     "output_type": "stream",
     "text": [
      "Defaulting to user installation because normal site-packages is not writeable\n",
      "\u001b[33mWARNING: Retrying (Retry(total=4, connect=None, read=None, redirect=None, status=None)) after connection broken by 'NewConnectionError('<pip._vendor.urllib3.connection.HTTPSConnection object at 0x7fdd94a72730>: Failed to establish a new connection: [Errno -3] Temporary failure in name resolution')': /simple/pandas/\u001b[0m\u001b[33m\n",
      "\u001b[0m\u001b[33mWARNING: Retrying (Retry(total=3, connect=None, read=None, redirect=None, status=None)) after connection broken by 'NewConnectionError('<pip._vendor.urllib3.connection.HTTPSConnection object at 0x7fdd94a72a90>: Failed to establish a new connection: [Errno -3] Temporary failure in name resolution')': /simple/pandas/\u001b[0m\u001b[33m\n",
      "\u001b[0m\u001b[33mWARNING: Retrying (Retry(total=2, connect=None, read=None, redirect=None, status=None)) after connection broken by 'NewConnectionError('<pip._vendor.urllib3.connection.HTTPSConnection object at 0x7fdd94a72c40>: Failed to establish a new connection: [Errno -3] Temporary failure in name resolution')': /simple/pandas/\u001b[0m\u001b[33m\n",
      "\u001b[0m\u001b[33mWARNING: Retrying (Retry(total=1, connect=None, read=None, redirect=None, status=None)) after connection broken by 'NewConnectionError('<pip._vendor.urllib3.connection.HTTPSConnection object at 0x7fdd94a72df0>: Failed to establish a new connection: [Errno -3] Temporary failure in name resolution')': /simple/pandas/\u001b[0m\u001b[33m\n",
      "\u001b[0m\u001b[33mWARNING: Retrying (Retry(total=0, connect=None, read=None, redirect=None, status=None)) after connection broken by 'NewConnectionError('<pip._vendor.urllib3.connection.HTTPSConnection object at 0x7fdd94a72fd0>: Failed to establish a new connection: [Errno -3] Temporary failure in name resolution')': /simple/pandas/\u001b[0m\u001b[33m\n",
      "\u001b[0m\u001b[31mERROR: Could not find a version that satisfies the requirement pandas (from versions: none)\u001b[0m\u001b[31m\n",
      "\u001b[0m\u001b[31mERROR: No matching distribution found for pandas\u001b[0m\u001b[31m\n",
      "\u001b[0mNote: you may need to restart the kernel to use updated packages.\n"
     ]
    }
   ],
   "source": [
    "pip install pandas"
   ]
  }
 ],
 "metadata": {
  "kernelspec": {
   "display_name": "Python 3 (ipykernel)",
   "language": "python",
   "name": "python3"
  },
  "language_info": {
   "codemirror_mode": {
    "name": "ipython",
    "version": 3
   },
   "file_extension": ".py",
   "mimetype": "text/x-python",
   "name": "python",
   "nbconvert_exporter": "python",
   "pygments_lexer": "ipython3",
   "version": "3.8.10"
  }
 },
 "nbformat": 4,
 "nbformat_minor": 5
}
